Workbook

Sheet Metrics
B2: Harborline (fictional): ARR bridge, retention and unit economics
B3: $ millions unless a line says otherwise. Blue on yellow = typed input, black = formula.
B5: ARR BRIDGE, LAST TWELVE MONTHS
B6: Line | D6: $ millions | F6: How it is calculated
B7: Beginning ARR (start of year) | D7: 40 | F7: given
B8: Minus churned ARR | D8: -4 | F8: customers that left or downgraded
B9: Plus expansion ARR | D9: 6 | F9: existing customers buying more
B10: Plus new logo ARR | D10: 18 | F10: brand-new customers
B11: Ending ARR (today) | D11: =SUM(D7:D10) | F11: 40.0 minus 4.0 plus 6.0 plus 18.0
B12: Net new ARR | D12: =D11-D7 | F12: 60.0 minus 40.0
B13: Gross new ARR (new plus expansion) | D13: =D10+D9 | F13: 18.0 plus 6.0
B15: GROWTH AND RETENTION FROM THE BRIDGE
B16: Metric | D16: Value | F16: Arithmetic
B17: ARR growth | D17: =D11/D7-1 | F17: 60.0 divided by 40.0, minus 1
B18: Gross revenue retention | D18: =(D7+D8)/D7 | F18: (40.0 minus 4.0) divided by 40.0
B19: Net revenue retention | D19: =(D7+D8+D9)/D7 | F19: (40.0 minus 4.0 plus 6.0) divided by 40.0
B21: COST INPUTS
B22: Input | D22: Value | F22: Note
B23: Revenue this year | D23: 50 | F23: ARR ramped from 40.0 to 60.0 during the year
B24: Gross margin | D24: 0.76 | F24: after hosting, support and implementation
B25: Gross profit | D25: =D23*D24 | F25: 50.0 times 76%
B26: Sales and marketing spend | D26: 20
B27: Net burn (cash out minus cash in) | D27: 5
B28: ARR per customer ($) | D28: 60000
B29: Customers today | D29: =D11*1000000/D28 | F29: ending ARR divided by ARR per customer
B30: New customers signed this year | D30: =D10*1000000/D28 | F30: new logo ARR divided by ARR per customer
B32: UNIT ECONOMICS
B33: Metric | D33: Value | F33: Arithmetic
B34: CAC (cost to win one customer, $) | D34: =D26*1000000/D30 | F34: $20.0M divided by 300 new customers
B35: CAC payback | D35: =D26/(D13*D24)*12 | F35: $20.0M divided by ($24.0M times 76%), times 12
B36: LTV (lifetime gross profit per customer, $) | D36: =D28*D24/(-D8/D7) | F36: $60,000 times 76%, divided by 10% churn
B37: LTV to CAC | D37: =D36/D34 | F37: $456,000 divided by $66,667
B38: Magic number | D38: =D12/D26 | F38: $20.0M net new ARR divided by $20.0M S&M
B39: Burn multiple | D39: =D27/D12 | F39: $5.0M net burn divided by $20.0M net new ARR
B40: Free cash flow margin | D40: =-D27/D23 | F40: negative $5.0M divided by $50.0M
B41: Rule of 40 score | D41: =(D17+D40)*100 | F41: 50.0% growth plus (10.0%) margin

Sheet Deal
B2: Harborline Series C: the round and the cap table
B3: $ millions unless a line says otherwise. Green = pulled from the Metrics sheet.
B5: THE ROUND
B6: New money in | D6: 100
B7: Post-money valuation | D7: 600
B8: Pre-money valuation | D8: =D7-D6
B9: Ownership bought | D9: =D6/D7
B10: Ending ARR (Metrics sheet) | D10: =Metrics!D11
B11: Entry EV to ARR | D11: =D7/D10
B12: Shares before the round | D12: =D23
B13: Price per share ($) | D13: =D8*1000000/D12
B14: New shares issued | D14: =D6*1000000/D13
B15: Shares after the round | D15: =D12+D14
B17: CAP TABLE BEFORE AND AFTER (fully diluted, option pool included)
B18: Holder | D18: Shares before | E18: % before | F18: Shares after | G18: % after
B19: Founders | D19: 30000000 | E19: =D19/D$23 | F19: =D19 | G19: =F19/F$23
B20: Earlier venture investors | D20: 15000000 | E20: =D20/D$23 | F20: =D20 | G20: =F20/F$23
B21: Employee option pool | D21: 5000000 | E21: =D21/D$23 | F21: =D21 | G21: =F21/F$23
B22: New growth investor (Series C preferred) | D22: 0 | E22: =D22/D$23 | F22: =D14 | G22: =F22/F$23
B23: Total | D23: =SUM(D19:D22) | E23: =D23/D$23 | F23: =SUM(F19:F22) | G23: =F23/F$23
B24: Founders after, the shortcut: 60.0% times pre over post | G24: =E19*D8/D7

Sheet Returns
B2: Harborline screen: three exits, the preference, MOIC and IRR
B3: $ millions. Five-year hold, one check in and one check out; equity value equals EV at exit (no debt or cash).
B5: DEAL INPUTS
B6: Investment (Deal sheet) | D6: =Deal!D6
B7: Ownership (Deal sheet) | D7: =Deal!D9
B8: ARR today (Metrics sheet) | D8: =Metrics!D11
B9: Liquidation preference (x invested) | D9: 1
B10: Preference amount | D10: =D6*D9
B11: Hold (years) | D11: 5
B13: STEP 3: THREE EXITS, FIVE YEARS OUT
B14: Scenario | D14: ARR in year 5 | E14: ARR CAGR from today | F14: Exit EV to ARR | G14: Equity value at exit | H14: Our stake as common
B15: Bear | D15: 90 | E15: =(D15/$D$8)^(1/$D$11)-1 | F15: 3 | G15: =D15*F15 | H15: =G15*$D$7
B16: Base | D16: 240 | E16: =(D16/$D$8)^(1/$D$11)-1 | F16: 7 | G16: =D16*F16 | H16: =G16*$D$7
B17: Bull | D17: 360 | E17: =(D17/$D$8)^(1/$D$11)-1 | F17: 9 | G17: =D17*F17 | H17: =G17*$D$7
B19: STEP 4: WHAT THE PREFERRED GETS
B20: Scenario | D20: Equity value | E20: As common (no preference) | F20: 1x preference amount | G20: 1x non-participating payout | H20: Which the investor picks | I20: 1x participating payout
B21: Bear | D21: =G15 | E21: =D21*$D$7 | F21: =$D$10 | G21: =MIN(D21,MAX(F21,E21)) | H21: =IF(F21>E21,"preference","convert to common") | I21: =MIN(F21,D21)+MAX(D21-F21,0)*$D$7
B22: Base | D22: =G16 | E22: =D22*$D$7 | F22: =$D$10 | G22: =MIN(D22,MAX(F22,E22)) | H22: =IF(F22>E22,"preference","convert to common") | I22: =MIN(F22,D22)+MAX(D22-F22,0)*$D$7
B23: Bull | D23: =G17 | E23: =D23*$D$7 | F23: =$D$10 | G23: =MIN(D23,MAX(F23,E23)) | H23: =IF(F23>E23,"preference","convert to common") | I23: =MIN(F23,D23)+MAX(D23-F23,0)*$D$7
B25: STEP 5: MOIC AND IRR ON THE $100.0 MILLION
B26: Scenario | D26: MOIC as common | E26: IRR as common | F26: MOIC, 1x non-part. | G26: IRR, 1x non-part. | H26: MOIC, 1x participating | I26: IRR, 1x participating
B27: Bear | D27: =E21/$D$6 | E27: =D27^(1/$D$11)-1 | F27: =G21/$D$6 | G27: =F27^(1/$D$11)-1 | H27: =I21/$D$6 | I27: =H27^(1/$D$11)-1
B28: Base | D28: =E22/$D$6 | E28: =D28^(1/$D$11)-1 | F28: =G22/$D$6 | G28: =F28^(1/$D$11)-1 | H28: =I22/$D$6 | I28: =H28^(1/$D$11)-1
B29: Bull | D29: =E23/$D$6 | E29: =D29^(1/$D$11)-1 | F29: =G23/$D$6 | G29: =F29^(1/$D$11)-1 | H29: =I23/$D$6 | I29: =H29^(1/$D$11)-1
B31: WHO GETS WHAT (1x non-participating)
B32: Scenario | D32: Equity value | E32: To preferred | F32: To founders, VCs and employees | G32: Their share
B33: Bear | D33: =D21 | E33: =G21 | F33: =D33-E33 | G33: =F33/D33
B34: Base | D34: =D22 | E34: =G22 | F34: =D34-E34 | G34: =F34/D34
B35: Bull | D35: =D23 | E35: =G23 | F35: =D35-E35 | G35: =F35/D35
B37: STEP 6: THE PRICE CHECK, SAME CHECK AT A $500.0 MILLION POST
B38: Item | D38: At $600.0M post | E38: At $500.0M post
B39: Post-money valuation | D39: =Deal!D7 | E39: 500
B40: Ownership | D40: =$D$6/D39 | E40: =$D$6/E39
B41: Base case payout (converts) | D41: =MAX($D$10,$G$16*D40) | E41: =MAX($D$10,$G$16*E40)
B42: Base case MOIC | D42: =D41/$D$6 | E42: =E41/$D$6
B43: Base case IRR | D43: =D42^(1/$D$11)-1 | E43: =E42^(1/$D$11)-1
B45: THE PREFERENCE IN FORMULAS (Bear row of step 4)
B46: Column | D46: Bear value | E46: Formula in the cell
B47: As common (no preference) | D47: =E21 | E47: E21: =D21*$D$7
B48: 1x preference amount | D48: =F21 | E48: F21: =$D$10
...
