Workbook

Sheet Cover
B2: Torvik Flow Systems
B3: Mid-cap industrial: pumps, valves and controls, aftermarket parts and service. A fictional company built for a two-hour DCF modeling test.
B5: VALUATION SETUP
B6: Valuation date | C6: 46022
B7: Fiscal year end | C7: December 31
B8: Units | C8: $ millions, except per share data
B9: Share price on the valuation date ($) | C9: 38
B10: Diluted shares (millions) | C10: 60
B12: SCENARIO SWITCH
B13: Scenario switch (1 = Bear, 2 = Base, 3 = Bull) | C13: 2 | D13: =CHOOSE(C13,"Bear","Base","Bull")
B14: Every growth and margin assumption on the Inputs tab reads this cell through a CHOOSE. Flip it and nothing else changes.
B16: OUTPUTS, LIVE FROM THE DCF TAB (CURRENT SCENARIO)
B17: FY2030E revenue | C17: =DCF!J8
B18: FY2030E EBITDA | C18: =DCF!J17
B19: WACC | C19: =WACC!C17
B20: Enterprise value | C20: =DCF!C41
B21: Implied share price ($) | C21: =DCF!C48
B22: Implied upside / (downside) vs the current price | C22: =DCF!C50
B24: SCENARIO SUMMARY (data table on the switch cell; values shown)
B25: Scenario | C25: FY2030E revenue | D25: FY2030E EBITDA margin | E25: FY2030E EBITDA | F25: FY2030E UFCF | G25: Enterprise value | H25: Implied share price | I25: vs $38.00
B26: Bear | C26: 1514.234 | D26: 0.168 | E26: 254.39131 | F26: 134.84818 | G26: 2080.9544 | H26: 29.432573 | I26: -0.22545859
B27: Base | C27: 1712.9009 | D27: 0.19 | E27: 325.45117 | F27: 178.14417 | G27: 2622.2078 | H27: 38.453464 | I27: 0.011933255
B28: Bull | C28: 1865.0878 | D28: 0.206 | E28: 384.2081 | F28: 212.20958 | G28: 3061.8804 | H28: 45.78134 | I28: 0.20477212
B30: COLOR KEY
B31: Blue on pale yellow: typed input (the pack's numbers and the assumptions)
B32: Black: formula
B33: Green: link to another tab
B35: TABS, IN BUILD ORDER
B36: Inputs | C36: historical income statement and ratios, segment build, assumptions block (Bear / Base / Bull)
B37: Schedules | C37: working capital by days, PP&E roll-forward
B38: Cost of debt | C38: tranches, weights, weighted pre-tax and after-tax cost
B39: Beta | C39: peer betas unlevered, median, relevered for Torvik
B40: WACC | C40: cost of equity by CAPM, after-tax cost of debt, market value weights
B41: DCF | C41: operating build, unlevered free cash flow, present values, terminal value, bridge to share price
B42: Sensitivity | C42: implied share price, WACC down and exit multiple across

Sheet Inputs
B1: Torvik Flow Systems: Inputs
B2: $ millions, except per share data. Fiscal year ends December 31.
B4: HISTORICAL INCOME STATEMENT AND RATIOS | C4: 2023A | D4: 2024A | E4: 2025A
B5: Revenue | C5: 1210 | D5: 1276 | E5: 1350
B6: Cost of sales | C6: -810 | D6: -845 | E6: -884
B7: Gross profit | C7: =SUM(C5:C6) | D7: =SUM(D5:D6) | E7: =SUM(E5:E6)
B8: SG&A | C8: -250 | D8: -260 | E8: -270
B9: EBIT | C9: =SUM(C7:C8) | D9: =SUM(D7:D8) | E9: =SUM(E7:E8)
B10: Interest expense | C10: -24 | D10: -24 | E10: -24
B11: Pretax income | C11: =SUM(C9:C10) | D11: =SUM(D9:D10) | E11: =SUM(E9:E10)
B12: Taxes | C12: -31.5 | D12: -36.75 | E12: -43
B13: Net income | C13: =SUM(C11:C12) | D13: =SUM(D11:D12) | E13: =SUM(E11:E12)
B14: Diluted shares (millions) | C14: 60 | D14: 60 | E14: 60
B15: Diluted EPS ($) | C15: =C13/C14 | D15: =D13/D14 | E15: =E13/E14
B16: Revenue growth | D16: =D5/C5-1 | E16: =E5/D5-1
B17: Gross margin | C17: =C7/C5 | D17: =D7/D5 | E17: =E7/E5
B18: SG&A as a percent of revenue | C18: =-C8/C5 | D18: =-D8/D5 | E18: =-E8/E5
B19: EBIT margin | C19: =C9/C5 | D19: =D9/D5 | E19: =E9/E5
B20: Effective tax rate | C20: =-C12/C11 | D20: =-D12/D11 | E20: =-E12/E11
B21: D&A (from the cash flow statement) | C21: 40 | D21: 42 | E21: 44
B22: EBITDA | C22: =C9+C21 | D22: =D9+D21 | E22: =E9+E21
B23: EBITDA margin | C23: =C22/C5 | D23: =D22/D5 | E23: =E22/E5
B24: Capex (from the cash flow statement) | C24: 48 | D24: 50 | E24: 54
B26: SEGMENT REVENUE BUILD | C26: 2023A | D26: 2024A | E26: 2025A
B27: Pumps | C27: 530 | D27: 548 | E27: 570
B28: Valves and Controls | C28: 385 | D28: 406 | E28: 430
B29: Aftermarket Parts and Service | C29: 295 | D29: 322 | E29: 350
B30: Total revenue | C30: =SUM(C27:C29) | D30: =SUM(D27:D29) | E30: =SUM(E27:E29)
B31: Check: segment total minus reported revenue (should read 0.0) | C31: =C30-C5 | D31: =D30-D5 | E31: =E30-E5
B32: Pumps growth | D32: =D27/C27-1 | E32: =E27/D27-1
B33: Valves and Controls growth | D33: =D28/C28-1 | E33: =E28/D28-1
B34: Aftermarket Parts and Service growth | D34: =D29/C29-1 | E34: =E29/D29-1
B35: Pumps mix | C35: =C27/C$30 | D35: =D27/D$30 | E35: =E27/E$30
B36: Valves and Controls mix | C36: =C28/C$30 | D36: =D28/D$30 | E36: =E28/E$30
B37: Aftermarket Parts and Service mix | C37: =C29/C$30 | D37: =D29/D$30 | E37: =E29/E$30
B39: ASSUMPTIONS: BEAR, BASE, BULL AND LIVE ROWS | C39: 2026E | D39: 2027E | E39: 2028E | F39: 2029E | G39: 2030E | I39: Formula in the 2026E column
B40: Scenario switch (from Cover: 1 = Bear, 2 = Base, 3 = Bull) | C40: =Cover!C13 | D40: =Cover!D13 | I40: =Cover!C13 (one cell, read by every live row)
B41: Pumps growth, Bear | C41: 0.01 | D41: 0 | E41: 0.01 | F41: 0.02 | G41: 0.02
B42: Pumps growth, Base | C42: 0.04 | D42: 0.04 | E42: 0.035 | F42: 0.035 | G42: 0.03
B43: Pumps growth, Bull | C43: 0.06 | D43: 0.06 | E43: 0.05 | F43: 0.05 | G43: 0.04
...

Sheet Schedules
B1: Torvik Flow Systems: Schedules
B2: $ millions, except per share data. Fiscal year ends December 31.
B4: WORKING CAPITAL BY DAYS | C4: 2022A | D4: 2023A | E4: 2024A | F4: 2025A | G4: 2026E | H4: 2027E | I4: 2028E | J4: 2029E | K4: 2030E
B5: Revenue (from the DCF tab) | D5: =DCF!C8 | E5: =DCF!D8 | F5: =DCF!E8 | G5: =DCF!F8 | H5: =DCF!G8 | I5: =DCF!H8 | J5: =DCF!I8 | K5: =DCF!J8
B6: Cost of sales (from the DCF tab) | D6: =DCF!C10 | E6: =DCF!D10 | F6: =DCF!E10 | G6: =DCF!F10 | H6: =DCF!G10 | I6: =DCF!H10 | J6: =DCF!I10 | K6: =DCF!J10
B7: Accounts receivable | C7: 190 | D7: 199 | E7: 210 | F7: 222 | G7: =G5*G14/365 | H7: =H5*H14/365 | I7: =I5*I14/365 | J7: =J5*J14/365 | K7: =K5*K14/365
B8: Inventory | C8: 195 | D8: 200 | E8: 208 | F8: 218 | G8: =-G6*G15/365 | H8: =-H6*H15/365 | I8: =-I6*I15/365 | J8: =-J6*J15/365 | K8: =-K6*K15/365
B9: Accounts payable | C9: 97 | D9: 100 | E9: 104 | F9: 109 | G9: =-G6*G16/365 | H9: =-H6*H16/365 | I9: =-I6*I16/365 | J9: =-J6*J16/365 | K9: =-K6*K16/365
B10: Accrued liabilities | C10: 46 | D10: 48 | E10: 51 | F10: 54 | G10: =G5*Inputs!C66 | H10: =H5*Inputs!D66 | I10: =I5*Inputs!E66 | J10: =J5*Inputs!F66 | K10: =K5*Inputs!G66
B11: Deferred revenue | C11: 23 | D11: 24 | E11: 26 | F11: 27 | G11: =G5*Inputs!C67 | H11: =H5*Inputs!D67 | I11: =I5*Inputs!E67 | J11: =J5*Inputs!F67 | K11: =K5*Inputs!G67
B12: Net working capital | C12: =C7+C8-C9-C10-C11 | D12: =D7+D8-D9-D10-D11 | E12: =E7+E8-E9-E10-E11 | F12: =F7+F8-F9-F10-F11 | G12: =G7+G8-G9-G10-G11 | H12: =H7+H8-H9-H10-H11 | I12: =I7+I8-I9-I10-I11 | J12: =J7+J8-J9-J10-J11 | K12: =K7+K8-K9-K10-K11
B13: (Increase) / decrease in NWC | D13: =C12-D12 | E13: =D12-E12 | F13: =E12-F12 | G13: =F12-G12 | H13: =G12-H12 | I13: =H12-I12 | J13: =I12-J12 | K13: =J12-K12
B14: DSO (days) | D14: =D7/D5*365 | E14: =E7/E5*365 | F14: =F7/F5*365 | G14: =Inputs!C63 | H14: =Inputs!D63 | I14: =Inputs!E63 | J14: =Inputs!F63 | K14: =Inputs!G63
B15: DIO (days) | D15: =D8/-D6*365 | E15: =E8/-E6*365 | F15: =F8/-F6*365 | G15: =Inputs!C64 | H15: =Inputs!D64 | I15: =Inputs!E64 | J15: =Inputs!F64 | K15: =Inputs!G64
B16: DPO (days) | D16: =D9/-D6*365 | E16: =E9/-E6*365 | F16: =F9/-F6*365 | G16: =Inputs!C65 | H16: =Inputs!D65 | I16: =Inputs!E65 | J16: =Inputs!F65 | K16: =Inputs!G65
B17: NWC as a percent of revenue | D17: =D12/D5 | E17: =E12/E5 | F17: =F12/F5 | G17: =G12/G5 | H17: =H12/H5 | I17: =I12/I5 | J17: =J12/J5 | K17: =K12/K5
B19: PP&E ROLL-FORWARD | C19: 2022A | D19: 2023A | E19: 2024A | F19: 2025A | G19: 2026E | H19: 2027E | I19: 2028E | J19: 2029E | K19: 2030E
B20: Beginning net PP&E | D20: =C23 | E20: =D23 | F20: =E23 | G20: =F23 | H20: =G23 | I20: =H23 | J20: =I23 | K20: =J23
B21: Plus: capex | D21: =DCF!C19 | E21: =DCF!D19 | F21: =DCF!E19 | G21: =DCF!F19 | H21: =DCF!G19 | I21: =DCF!H19 | J21: =DCF!I19 | K21: =DCF!J19
B22: Less: depreciation and amortization | D22: =-DCF!C16 | E22: =-DCF!D16 | F22: =-DCF!E16 | G22: =-DCF!F16 | H22: =-DCF!G16 | I22: =-DCF!H16 | J22: =-DCF!I16 | K22: =-DCF!J16
B23: Ending net PP&E | C23: 384 | D23: =SUM(D20:D22) | E23: =SUM(E20:E22) | F23: =SUM(F20:F22) | G23: =SUM(G20:G22) | H23: =SUM(H20:H22) | I23: =SUM(I20:I22) | J23: =SUM(J20:J22) | K23: =SUM(K20:K22)
B24: Capex as a percent of revenue | D24: =D21/D5 | E24: =E21/E5 | F24: =F21/F5 | G24: =G21/G5 | H24: =H21/H5 | I24: =I21/I5 | J24: =J21/J5 | K24: =K21/K5
B25: D&A as a percent of revenue | D25: =-D22/D5 | E25: =-E22/E5 | F25: =-F22/F5 | G25: =-G22/G5 | H25: =-H22/H5 | I25: =-I22/I5 | J25: =-J22/J5 | K25: =-K22/K5

Sheet Cost of debt
B1: Torvik Flow Systems: Cost of debt
B2: $ millions, except per share data. Fiscal year ends December 31.
B4: COST OF DEBT
B5: Tranche | C5: Principal | D5: Weight | E5: Rate | F5: Principal x rate
B6: Term loan B | C6: 250 | D6: =C6/C$8 | E6: 0.0575 | F6: =C6*E6
B7: Senior notes | C7: 150 | D7: =C7/C$8 | E7: 0.065 | F7: =C7*E7
B8: Total debt and weighted pre-tax cost | C8: =SUM(C6:C7) | D8: =SUM(D6:D7) | E8: =F8/C8 | F8: =SUM(F6:F7)
B9: Tax rate (from the Inputs tab) | E9: =Inputs!C68
B10: After-tax cost of debt at a 25% tax rate | E10: =E8*(1-E9)
B11: Tie: historical interest expense of 24.0 a year against 400.0 of debt at 6.03% is 24.1, within rounding.

Sheet Beta
B1: Torvik Flow Systems: Beta
B2: Peers are fictional. Debt and equity value in $ millions.
B4: PEER BETAS, UNLEVERED AND RELEVERED
B5: Company | C5: Levered beta | D5: Debt | E5: Equity value | F5: D / E | G5: Tax rate | H5: Unlevered beta
B6: Peer A (large-cap pumps) | C6: 1.2 | D6: 600 | E6: 3000 | F6: =D6/E6 | G6: 0.25 | H6: =C6/(1+(1-G6)*F6)
B7: Peer B (valves) | C7: 1.05 | D7: 300 | E7: 2500 | F7: =D7/E7 | G7: 0.25 | H7: =C7/(1+(1-G7)*F7)
B8: Peer C (industrial controls) | C8: 1.35 | D8: 1200 | E8: 4000 | F8: =D8/E8 | G8: 0.25 | H8: =C8/(1+(1-G8)*F8)
B9: Peer D (flow equipment, small cap) | C9: 0.95 | D9: 200 | E9: 1800 | F9: =D9/E9 | G9: 0.25 | H9: =C9/(1+(1-G9)*F9)
B10: Peer E (fluid handling) | C10: 1.15 | D10: 900 | E10: 3600 | F10: =D10/E10 | G10: 0.25 | H10: =C10/(1+(1-G10)*F10)
B11: Median unlevered beta | H11: =MEDIAN(H6:H10)
B12: Mean unlevered beta (for reference) | H12: =AVERAGE(H6:H10)
B13: Torvik debt to equity (400.0 / market cap) | D13: ='Cost of debt'!C8 | E13: =WACC!C13 | F13: =D13/E13 | G13: =Inputs!C68
B14: Torvik relevered beta | H14: =H11*(1+(1-G13)*F13)

Sheet WACC
B1: Torvik Flow Systems: WACC
B2: $ millions, except per share data. Fiscal year ends December 31.
B4: WACC
B5: Risk-free rate (from the pack) | C5: 0.045
B6: Equity risk premium (from the pack) | C6: 0.05
B7: Relevered beta | C7: =Beta!H14
B8: Cost of equity = risk-free + beta times ERP | C8: =C5+C7*C6
B9: Pre-tax cost of debt | C9: ='Cost of debt'!E8
B10: After-tax cost of debt | C10: ='Cost of debt'!E10
B11: Share price on the valuation date ($) | C11: =Cover!C9
B12: Diluted shares (millions) | C12: =Cover!C10
B13: Equity value (market cap) | C13: =C11*C12
B14: Total debt | C14: ='Cost of debt'!C8
B15: Equity weight | C15: =C13/(C13+C14)
B16: Debt weight | C16: =C14/(C13+C14)
B17: WACC | C17: =C15*C8+C16*C10

Sheet DCF
B1: Torvik Flow Systems: DCF
B2: $ millions, except per share data. Fiscal year ends December 31.
B4: OPERATING BUILD | C4: 2023A | D4: 2024A | E4: 2025A | F4: 2026E | G4: 2027E | H4: 2028E | I4: 2029E | J4: 2030E | L4: Formula in the 2026E column
B5: Pumps | C5: =Inputs!C27 | D5: =Inputs!D27 | E5: =Inputs!E27 | F5: =E5*(1+Inputs!C44) | G5: =F5*(1+Inputs!D44) | H5: =G5*(1+Inputs!E44) | I5: =H5*(1+Inputs!F44) | J5: =I5*(1+Inputs!G44) | L5: =E5*(1+Inputs!C44)
B6: Valves and Controls | C6: =Inputs!C28 | D6: =Inputs!D28 | E6: =Inputs!E28 | F6: =E6*(1+Inputs!C48) | G6: =F6*(1+Inputs!D48) | H6: =G6*(1+Inputs!E48) | I6: =H6*(1+Inputs!F48) | J6: =I6*(1+Inputs!G48) | L6: =E6*(1+Inputs!C48)
B7: Aftermarket Parts and Service | C7: =Inputs!C29 | D7: =Inputs!D29 | E7: =Inputs!E29 | F7: =E7*(1+Inputs!C52) | G7: =F7*(1+Inputs!D52) | H7: =G7*(1+Inputs!E52) | I7: =H7*(1+Inputs!F52) | J7: =I7*(1+Inputs!G52) | L7: =E7*(1+Inputs!C52)
B8: Total revenue | C8: =SUM(C5:C7) | D8: =SUM(D5:D7) | E8: =SUM(E5:E7) | F8: =SUM(F5:F7) | G8: =SUM(G5:G7) | H8: =SUM(H5:H7) | I8: =SUM(I5:I7) | J8: =SUM(J5:J7) | L8: =SUM(F5:F7)
B9: Revenue growth | D9: =D8/C8-1 | E9: =E8/D8-1 | F9: =F8/E8-1 | G9: =G8/F8-1 | H9: =H8/G8-1 | I9: =I8/H8-1 | J9: =J8/I8-1 | L9: =F8/E8-1
B10: Cost of sales | C10: =Inputs!C6 | D10: =Inputs!D6 | E10: =Inputs!E6 | F10: =-F8*(1-Inputs!C56) | G10: =-G8*(1-Inputs!D56) | H10: =-H8*(1-Inputs!E56) | I10: =-I8*(1-Inputs!F56) | J10: =-J8*(1-Inputs!G56) | L10: =-F8*(1-Inputs!C56)
B11: Gross profit | C11: =C8+C10 | D11: =D8+D10 | E11: =E8+E10 | F11: =F8+F10 | G11: =G8+G10 | H11: =H8+H10 | I11: =I8+I10 | J11: =J8+J10 | L11: =F8+F10
B12: Gross margin | C12: =C11/C8 | D12: =D11/D8 | E12: =E11/E8 | F12: =F11/F8 | G12: =G11/G8 | H12: =H11/H8 | I12: =I11/I8 | J12: =J11/J8 | L12: =F11/F8
B13: SG&A | C13: =Inputs!C8 | D13: =Inputs!D8 | E13: =Inputs!E8 | F13: =-F8*Inputs!C60 | G13: =-G8*Inputs!D60 | H13: =-H8*Inputs!E60 | I13: =-I8*Inputs!F60 | J13: =-J8*Inputs!G60 | L13: =-F8*Inputs!C60
B14: EBIT | C14: =C11+C13 | D14: =D11+D13 | E14: =E11+E13 | F14: =F11+F13 | G14: =G11+G13 | H14: =H11+H13 | I14: =I11+I13 | J14: =J11+J13 | L14: =F11+F13
B15: EBIT margin | C15: =C14/C8 | D15: =D14/D8 | E15: =E14/E8 | F15: =F14/F8 | G15: =G14/G8 | H15: =H14/H8 | I15: =I14/I8 | J15: =J14/J8 | L15: =F14/F8
B16: D&A | C16: =Inputs!C21 | D16: =Inputs!D21 | E16: =Inputs!E21 | F16: =F8*Inputs!C61 | G16: =G8*Inputs!D61 | H16: =H8*Inputs!E61 | I16: =I8*Inputs!F61 | J16: =J8*Inputs!G61 | L16: =F8*Inputs!C61
B17: EBITDA | C17: =C14+C16 | D17: =D14+D16 | E17: =E14+E16 | F17: =F14+F16 | G17: =G14+G16 | H17: =H14+H16 | I17: =I14+I16 | J17: =J14+J16 | L17: =F14+F16
B18: EBITDA margin | C18: =C17/C8 | D18: =D17/D8 | E18: =E17/E8 | F18: =F17/F8 | G18: =G17/G8 | H18: =H17/H8 | I18: =I17/I8 | J18: =J17/J8 | L18: =F17/F8
B19: Capex | C19: =Inputs!C24 | D19: =Inputs!D24 | E19: =Inputs!E24 | F19: =F8*Inputs!C62 | G19: =G8*Inputs!D62 | H19: =H8*Inputs!E62 | I19: =I8*Inputs!F62 | J19: =J8*Inputs!G62 | L19: =F8*Inputs!C62
B21: UNLEVERED FREE CASH FLOW AND PRESENT VALUE | C21: 2023A | D21: 2024A | E21: 2025A | F21: 2026E | G21: 2027E | H21: 2028E | I21: 2029E | J21: 2030E | L21: Formula in the 2026E column
B22: EBIT | C22: =C14 | D22: =D14 | E22: =E14 | F22: =F14 | G22: =G14 | H22: =H14 | I22: =I14 | J22: =J14 | L22: =F14
B23: Less: taxes on EBIT at 25% | C23: =-C22*Inputs!C20 | D23: =-D22*Inputs!D20 | E23: =-E22*Inputs!E20 | F23: =-F22*Inputs!C68 | G23: =-G22*Inputs!D68 | H23: =-H22*Inputs!E68 | I23: =-I22*Inputs!F68 | J23: =-J22*Inputs!G68 | L23: =-F22*Inputs!C68
B24: NOPAT | C24: =C22+C23 | D24: =D22+D23 | E24: =E22+E23 | F24: =F22+F23 | G24: =G22+G23 | H24: =H22+H23 | I24: =I22+I23 | J24: =J22+J23 | L24: =F22+F23
B25: Plus: D&A | C25: =C16 | D25: =D16 | E25: =E16 | F25: =F16 | G25: =G16 | H25: =H16 | I25: =I16 | J25: =J16 | L25: =F16
B26: Less: capex | C26: =-C19 | D26: =-D19 | E26: =-E19 | F26: =-F19 | G26: =-G19 | H26: =-H19 | I26: =-I19 | J26: =-J19 | L26: =-F19
B27: Less: increase in NWC | C27: =Schedules!D13 | D27: =Schedules!E13 | E27: =Schedules!F13 | F27: =Schedules!G13 | G27: =Schedules!H13 | H27: =Schedules!I13 | I27: =Schedules!J13 | J27: =Schedules!K13 | L27: =Schedules!G13
B28: Unlevered free cash flow | C28: =SUM(C24:C27) | D28: =SUM(D24:D27) | E28: =SUM(E24:E27) | F28: =SUM(F24:F27) | G28: =SUM(G24:G27) | H28: =SUM(H24:H27) | I28: =SUM(I24:I27) | J28: =SUM(J24:J27) | L28: =SUM(F24:F27)
B29: Year fraction from the valuation date | F29: 1 | G29: 1 | H29: 1 | I29: 1 | J29: 1 | L29: Input: 1.00, the valuation date is the fiscal year end
B30: Discount period (mid-year) | F30: =F29/2 | G30: =F30+(F29+G29)/2 | H30: =G30+(G29+H29)/2 | I30: =H30+(H29+I29)/2 | J30: =I30+(I29+J29)/2 | L30: =F29/2
B31: Discount factor at 9.16% WACC | F31: =1/(1+WACC!$C$17)^F30 | G31: =1/(1+WACC!$C$17)^G30 | H31: =1/(1+WACC!$C$17)^H30 | I31: =1/(1+WACC!$C$17)^I30 | J31: =1/(1+WACC!$C$17)^J30 | L31: =1/(1+WACC!$C$17)^F30
B32: Present value of UFCF | F32: =F28*F31 | G32: =G28*G31 | H32: =H28*H31 | I32: =I28*I31 | J32: =J28*J31 | L32: =F28*F31
B34: TERMINAL VALUE TO SHARE PRICE | C34: Value
B35: Sum of present values, FY2026E to FY2030E | C35: =SUM(F32:J32)
B36: FY2030E EBITDA | C36: =J17
B37: Exit multiple | C37: 9.5
B38: Terminal value at the end of FY2030 | C38: =C36*C37
B39: Discount factor, 5.0 years | C39: =1/(1+WACC!$C$17)^SUM(F29:J29)
B40: Present value of terminal value | C40: =C38*C39
B41: Enterprise value | C41: =C35+C40
B42: Terminal value as a share of enterprise value | C42: =C40/C41
B43: Less: total debt | C43: =-'Cost of debt'!C8
...

Sheet Sensitivity
B1: Torvik Flow Systems: Sensitivity
B2: Implied share price ($) by WACC (down) and exit multiple (across).
B4: SENSITIVITY: IMPLIED SHARE PRICE, WACC (DOWN) VS EXIT MULTIPLE (ACROSS)
B5: Body: an Excel data table, WACC as the column input, exit multiple as the row input. Values shown.
B6: WACC step (down the side) | C6: 0.005
B7: Exit multiple step (across the top) | C7: 0.5
B9: WACC (down) / exit multiple (across) | C9: =DCF!C48 | D9: =DCF!$C$37-2*$C$7 | E9: =DCF!$C$37-1*$C$7 | F9: =DCF!$C$37 | G9: =DCF!$C$37+1*$C$7 | H9: =DCF!$C$37+2*$C$7
C10: =WACC!$C$17-2*$C$6 | D10: 36.596115 | E10: 38.42789 | F10: 40.259666 | G10: 42.091441 | H10: 43.923217
C11: =WACC!$C$17-1*$C$6 | D11: 35.764539 | E11: 37.554558 | F11: 39.344577 | G11: 41.134595 | H11: 42.924614
C12: =WACC!$C$17 | D12: 34.954665 | E12: 36.704064 | F12: 38.453464 | G12: 40.202863 | H12: 41.952262
C13: =WACC!$C$17+1*$C$6 | D13: 34.165822 | E13: 35.875703 | F13: 37.585584 | G13: 39.295464 | H13: 41.005345
C14: =WACC!$C$17+2*$C$6 | D14: 33.397363 | E14: 35.068791 | F14: 36.74022 | G14: 38.411648 | H14: 40.083077
